[2025-01-19T05:40:48.821+0000] {local_task_job_runner.py:123} INFO - ::group::Pre task execution logs
[2025-01-19T05:40:49.190+0000] {taskinstance.py:2613} INFO - Dependencies all met for dep_context=non-requeueable deps ti=<TaskInstance: testing_first_dag.testing_first_task scheduled__2024-01-24T00:00:00+00:00 [queued]>
[2025-01-19T05:40:49.293+0000] {taskinstance.py:2613} INFO - Dependencies all met for dep_context=requeueable deps ti=<TaskInstance: testing_first_dag.testing_first_task scheduled__2024-01-24T00:00:00+00:00 [queued]>
[2025-01-19T05:40:49.303+0000] {taskinstance.py:2866} INFO - Starting attempt 1 of 6
[2025-01-19T05:40:49.508+0000] {taskinstance.py:2889} INFO - Executing <Task(BashOperator): testing_first_task> on 2024-01-24 00:00:00+00:00
[2025-01-19T05:40:49.539+0000] {warnings.py:112} WARNING - /home/***/.local/lib/python3.12/site-packages/***/task/task_runner/standard_task_runner.py:70: DeprecationWarning: This process (pid=112) is multi-threaded, use of fork() may lead to deadlocks in the child.
  pid = os.fork()

[2025-01-19T05:40:49.567+0000] {standard_task_runner.py:72} INFO - Started process 143 to run task
[2025-01-19T05:40:49.578+0000] {standard_task_runner.py:104} INFO - Running: ['***', 'tasks', 'run', 'testing_first_dag', 'testing_first_task', 'scheduled__2024-01-24T00:00:00+00:00', '--job-id', '13', '--raw', '--subdir', 'DAGS_FOLDER/testing_dag.py', '--cfg-path', '/tmp/tmp6i5bi6r3']
[2025-01-19T05:40:49.600+0000] {standard_task_runner.py:105} INFO - Job 13: Subtask testing_first_task
[2025-01-19T05:40:50.356+0000] {task_command.py:467} INFO - Running <TaskInstance: testing_first_dag.testing_first_task scheduled__2024-01-24T00:00:00+00:00 [running]> on host 4cc7b150d909
[2025-01-19T05:40:51.701+0000] {taskinstance.py:3132} INFO - Exporting env vars: AIRFLOW_CTX_DAG_OWNER='ikrar' AIRFLOW_CTX_DAG_ID='testing_first_dag' AIRFLOW_CTX_TASK_ID='testing_first_task' AIRFLOW_CTX_EXECUTION_DATE='2024-01-24T00:00:00+00:00' AIRFLOW_CTX_TRY_NUMBER='1' AIRFLOW_CTX_DAG_RUN_ID='scheduled__2024-01-24T00:00:00+00:00'
[2025-01-19T05:40:51.724+0000] {taskinstance.py:731} INFO - ::endgroup::
[2025-01-19T05:40:53.393+0000] {subprocess.py:78} INFO - Tmp dir root location: /tmp
[2025-01-19T05:40:53.490+0000] {subprocess.py:88} INFO - Running command: ['/usr/bin/bash', '-c', 'Testing first task']
[2025-01-19T05:40:53.819+0000] {subprocess.py:99} INFO - Output:
[2025-01-19T05:40:54.105+0000] {subprocess.py:106} INFO - /usr/bin/bash: line 1: Testing: command not found
[2025-01-19T05:40:54.117+0000] {subprocess.py:110} INFO - Command exited with return code 127
[2025-01-19T05:40:54.231+0000] {taskinstance.py:3311} ERROR - Task failed with exception
Traceback (most recent call last):
  File "/home/airflow/.local/lib/python3.12/site-packages/airflow/models/taskinstance.py", line 767, in _execute_task
    result = _execute_callable(context=context, **execute_callable_kwargs)
             ^^^^^^^^^^^^^^^^^^^^^^^^^^^^^^^^^^^^^^^^^^^^^^^^^^^^^^^^^^^^^
  File "/home/airflow/.local/lib/python3.12/site-packages/airflow/models/taskinstance.py", line 733, in _execute_callable
    return ExecutionCallableRunner(
           ^^^^^^^^^^^^^^^^^^^^^^^^
  File "/home/airflow/.local/lib/python3.12/site-packages/airflow/utils/operator_helpers.py", line 252, in run
    return self.func(*args, **kwargs)
           ^^^^^^^^^^^^^^^^^^^^^^^^^^
  File "/home/airflow/.local/lib/python3.12/site-packages/airflow/models/baseoperator.py", line 422, in wrapper
    return func(self, *args, **kwargs)
           ^^^^^^^^^^^^^^^^^^^^^^^^^^^
  File "/home/airflow/.local/lib/python3.12/site-packages/airflow/operators/bash.py", line 276, in execute
    raise AirflowException(
airflow.exceptions.AirflowException: Bash command failed. The command returned a non-zero exit code 127.
[2025-01-19T05:40:54.338+0000] {taskinstance.py:1225} INFO - Marking task as UP_FOR_RETRY. dag_id=testing_first_dag, task_id=testing_first_task, run_id=scheduled__2024-01-24T00:00:00+00:00, execution_date=20240124T000000, start_date=20250119T054049, end_date=20250119T054054
[2025-01-19T05:40:54.451+0000] {taskinstance.py:340} INFO - ::group::Post task execution logs
[2025-01-19T05:40:54.456+0000] {standard_task_runner.py:124} ERROR - Failed to execute job 13 for task testing_first_task (Bash command failed. The command returned a non-zero exit code 127.; 143)
Traceback (most recent call last):
  File "/home/airflow/.local/lib/python3.12/site-packages/airflow/task/task_runner/standard_task_runner.py", line 117, in _start_by_fork
    ret = args.func(args, dag=self.dag)
          ^^^^^^^^^^^^^^^^^^^^^^^^^^^^^
  File "/home/airflow/.local/lib/python3.12/site-packages/airflow/cli/cli_config.py", line 49, in command
    return func(*args, **kwargs)
           ^^^^^^^^^^^^^^^^^^^^^
  File "/home/airflow/.local/lib/python3.12/site-packages/airflow/utils/cli.py", line 116, in wrapper
    return f(*args, **kwargs)
           ^^^^^^^^^^^^^^^^^^
  File "/home/airflow/.local/lib/python3.12/site-packages/airflow/cli/commands/task_command.py", line 483, in task_run
    task_return_code = _run_task_by_selected_method(args, _dag, ti)
                       ^^^^^^^^^^^^^^^^^^^^^^^^^^^^^^^^^^^^^^^^^^^^
  File "/home/airflow/.local/lib/python3.12/site-packages/airflow/cli/commands/task_command.py", line 256, in _run_task_by_selected_method
    return _run_raw_task(args, ti)
           ^^^^^^^^^^^^^^^^^^^^^^^
  File "/home/airflow/.local/lib/python3.12/site-packages/airflow/cli/commands/task_command.py", line 341, in _run_raw_task
    return ti._run_raw_task(
           ^^^^^^^^^^^^^^^^^
  File "/home/airflow/.local/lib/python3.12/site-packages/airflow/utils/session.py", line 97, in wrapper
    return func(*args, session=session, **kwargs)
           ^^^^^^^^^^^^^^^^^^^^^^^^^^^^^^^^^^^^^^
  File "/home/airflow/.local/lib/python3.12/site-packages/airflow/models/taskinstance.py", line 3005, in _run_raw_task
    return _run_raw_task(
           ^^^^^^^^^^^^^^
  File "/home/airflow/.local/lib/python3.12/site-packages/airflow/models/taskinstance.py", line 273, in _run_raw_task
    TaskInstance._execute_task_with_callbacks(
  File "/home/airflow/.local/lib/python3.12/site-packages/airflow/models/taskinstance.py", line 3159, in _execute_task_with_callbacks
    result = self._execute_task(context, task_orig)
             ^^^^^^^^^^^^^^^^^^^^^^^^^^^^^^^^^^^^^^
  File "/home/airflow/.local/lib/python3.12/site-packages/airflow/models/taskinstance.py", line 3183, in _execute_task
    return _execute_task(self, context, task_orig)
           ^^^^^^^^^^^^^^^^^^^^^^^^^^^^^^^^^^^^^^^
  File "/home/airflow/.local/lib/python3.12/site-packages/airflow/models/taskinstance.py", line 767, in _execute_task
    result = _execute_callable(context=context, **execute_callable_kwargs)
             ^^^^^^^^^^^^^^^^^^^^^^^^^^^^^^^^^^^^^^^^^^^^^^^^^^^^^^^^^^^^^
  File "/home/airflow/.local/lib/python3.12/site-packages/airflow/models/taskinstance.py", line 733, in _execute_callable
    return ExecutionCallableRunner(
           ^^^^^^^^^^^^^^^^^^^^^^^^
  File "/home/airflow/.local/lib/python3.12/site-packages/airflow/utils/operator_helpers.py", line 252, in run
    return self.func(*args, **kwargs)
           ^^^^^^^^^^^^^^^^^^^^^^^^^^
  File "/home/airflow/.local/lib/python3.12/site-packages/airflow/models/baseoperator.py", line 422, in wrapper
    return func(self, *args, **kwargs)
           ^^^^^^^^^^^^^^^^^^^^^^^^^^^
  File "/home/airflow/.local/lib/python3.12/site-packages/airflow/operators/bash.py", line 276, in execute
    raise AirflowException(
airflow.exceptions.AirflowException: Bash command failed. The command returned a non-zero exit code 127.
[2025-01-19T05:40:54.667+0000] {local_task_job_runner.py:266} INFO - Task exited with return code 1
[2025-01-19T05:40:54.829+0000] {local_task_job_runner.py:245} INFO - ::endgroup::
[2025-01-19T05:40:55.123+0000] {standard_task_runner.py:217} INFO - Process not found (most likely exited), stop collecting metrics
