[2025-01-27T06:14:23.162+0000] {local_task_job_runner.py:123} INFO - ::group::Pre task execution logs
[2025-01-27T06:14:23.217+0000] {taskinstance.py:2613} INFO - Dependencies all met for dep_context=non-requeueable deps ti=<TaskInstance: scraping_etl.testing_scraping scheduled__2025-01-26T00:00:00+00:00 [queued]>
[2025-01-27T06:14:23.253+0000] {taskinstance.py:2613} INFO - Dependencies all met for dep_context=requeueable deps ti=<TaskInstance: scraping_etl.testing_scraping scheduled__2025-01-26T00:00:00+00:00 [queued]>
[2025-01-27T06:14:23.256+0000] {taskinstance.py:2866} INFO - Starting attempt 4 of 6
[2025-01-27T06:14:23.308+0000] {taskinstance.py:2889} INFO - Executing <Task(PythonOperator): testing_scraping> on 2025-01-26 00:00:00+00:00
[2025-01-27T06:14:23.344+0000] {warnings.py:112} WARNING - /home/***/.local/lib/python3.12/site-packages/***/task/task_runner/standard_task_runner.py:70: DeprecationWarning: This process (pid=210) is multi-threaded, use of fork() may lead to deadlocks in the child.
  pid = os.fork()

[2025-01-27T06:14:23.350+0000] {standard_task_runner.py:72} INFO - Started process 212 to run task
[2025-01-27T06:14:23.346+0000] {standard_task_runner.py:104} INFO - Running: ['***', 'tasks', 'run', 'scraping_etl', 'testing_scraping', 'scheduled__2025-01-26T00:00:00+00:00', '--job-id', '61', '--raw', '--subdir', 'DAGS_FOLDER/pipeline_scraping.py', '--cfg-path', '/tmp/tmprepoov7h']
[2025-01-27T06:14:23.355+0000] {standard_task_runner.py:105} INFO - Job 61: Subtask testing_scraping
[2025-01-27T06:14:23.524+0000] {task_command.py:467} INFO - Running <TaskInstance: scraping_etl.testing_scraping scheduled__2025-01-26T00:00:00+00:00 [running]> on host dfba9d948bec
[2025-01-27T06:14:23.792+0000] {taskinstance.py:3132} INFO - Exporting env vars: AIRFLOW_CTX_DAG_OWNER='ikrar' AIRFLOW_CTX_DAG_ID='scraping_etl' AIRFLOW_CTX_TASK_ID='testing_scraping' AIRFLOW_CTX_EXECUTION_DATE='2025-01-26T00:00:00+00:00' AIRFLOW_CTX_TRY_NUMBER='4' AIRFLOW_CTX_DAG_RUN_ID='scheduled__2025-01-26T00:00:00+00:00'
[2025-01-27T06:14:23.795+0000] {taskinstance.py:731} INFO - ::endgroup::
[2025-01-27T06:14:23.841+0000] {logger.py:11} INFO - ====== WebDriver manager ======
[2025-01-27T06:14:23.922+0000] {logger.py:11} INFO - Get LATEST chromedriver version for google-chrome
[2025-01-27T06:14:24.420+0000] {logger.py:11} INFO - About to download new driver from https://chromedriver.storage.googleapis.com/114.0.5735.90/chromedriver_linux64.zip
[2025-01-27T06:14:24.606+0000] {logger.py:11} INFO - Driver downloading response is 200
[2025-01-27T06:14:27.109+0000] {logger.py:11} INFO - Get LATEST chromedriver version for google-chrome
[2025-01-27T06:14:37.172+0000] {taskinstance.py:3311} ERROR - Task failed with exception
Traceback (most recent call last):
  File "/home/airflow/.local/lib/python3.12/site-packages/urllib3/connection.py", line 199, in _new_conn
    sock = connection.create_connection(
           ^^^^^^^^^^^^^^^^^^^^^^^^^^^^^
  File "/home/airflow/.local/lib/python3.12/site-packages/urllib3/util/connection.py", line 60, in create_connection
    for res in socket.getaddrinfo(host, port, family, socket.SOCK_STREAM):
               ^^^^^^^^^^^^^^^^^^^^^^^^^^^^^^^^^^^^^^^^^^^^^^^^^^^^^^^^^^
  File "/usr/local/lib/python3.12/socket.py", line 976, in getaddrinfo
    for res in _socket.getaddrinfo(host, port, family, type, proto, flags):
               ^^^^^^^^^^^^^^^^^^^^^^^^^^^^^^^^^^^^^^^^^^^^^^^^^^^^^^^^^^^
socket.gaierror: [Errno -3] Temporary failure in name resolution

The above exception was the direct cause of the following exception:

Traceback (most recent call last):
  File "/home/airflow/.local/lib/python3.12/site-packages/urllib3/connectionpool.py", line 789, in urlopen
    response = self._make_request(
               ^^^^^^^^^^^^^^^^^^^
  File "/home/airflow/.local/lib/python3.12/site-packages/urllib3/connectionpool.py", line 490, in _make_request
    raise new_e
  File "/home/airflow/.local/lib/python3.12/site-packages/urllib3/connectionpool.py", line 466, in _make_request
    self._validate_conn(conn)
  File "/home/airflow/.local/lib/python3.12/site-packages/urllib3/connectionpool.py", line 1095, in _validate_conn
    conn.connect()
  File "/home/airflow/.local/lib/python3.12/site-packages/urllib3/connection.py", line 693, in connect
    self.sock = sock = self._new_conn()
                       ^^^^^^^^^^^^^^^^
  File "/home/airflow/.local/lib/python3.12/site-packages/urllib3/connection.py", line 206, in _new_conn
    raise NameResolutionError(self.host, self, e) from e
urllib3.exceptions.NameResolutionError: <urllib3.connection.HTTPSConnection object at 0x7ff0b2cc6210>: Failed to resolve 'chromedriver.storage.googleapis.com' ([Errno -3] Temporary failure in name resolution)

The above exception was the direct cause of the following exception:

Traceback (most recent call last):
  File "/home/airflow/.local/lib/python3.12/site-packages/requests/adapters.py", line 667, in send
    resp = conn.urlopen(
           ^^^^^^^^^^^^^
  File "/home/airflow/.local/lib/python3.12/site-packages/urllib3/connectionpool.py", line 843, in urlopen
    retries = retries.increment(
              ^^^^^^^^^^^^^^^^^^
  File "/home/airflow/.local/lib/python3.12/site-packages/urllib3/util/retry.py", line 519, in increment
    raise MaxRetryError(_pool, url, reason) from reason  # type: ignore[arg-type]
    ^^^^^^^^^^^^^^^^^^^^^^^^^^^^^^^^^^^^^^^^^^^^^^^^^^^
urllib3.exceptions.MaxRetryError: HTTPSConnectionPool(host='chromedriver.storage.googleapis.com', port=443): Max retries exceeded with url: /LATEST_RELEASE (Caused by NameResolutionError("<urllib3.connection.HTTPSConnection object at 0x7ff0b2cc6210>: Failed to resolve 'chromedriver.storage.googleapis.com' ([Errno -3] Temporary failure in name resolution)"))

During handling of the above exception, another exception occurred:

Traceback (most recent call last):
  File "/home/airflow/.local/lib/python3.12/site-packages/webdriver_manager/core/http.py", line 32, in get
    resp = requests.get(
           ^^^^^^^^^^^^^
  File "/home/airflow/.local/lib/python3.12/site-packages/requests/api.py", line 73, in get
    return request("get", url, params=params, **kwargs)
           ^^^^^^^^^^^^^^^^^^^^^^^^^^^^^^^^^^^^^^^^^^^^
  File "/home/airflow/.local/lib/python3.12/site-packages/requests/api.py", line 59, in request
    return session.request(method=method, url=url, **kwargs)
           ^^^^^^^^^^^^^^^^^^^^^^^^^^^^^^^^^^^^^^^^^^^^^^^^^
  File "/home/airflow/.local/lib/python3.12/site-packages/requests/sessions.py", line 589, in request
    resp = self.send(prep, **send_kwargs)
           ^^^^^^^^^^^^^^^^^^^^^^^^^^^^^^
  File "/home/airflow/.local/lib/python3.12/site-packages/requests/sessions.py", line 703, in send
    r = adapter.send(request, **kwargs)
        ^^^^^^^^^^^^^^^^^^^^^^^^^^^^^^^
  File "/home/airflow/.local/lib/python3.12/site-packages/requests/adapters.py", line 700, in send
    raise ConnectionError(e, request=request)
requests.exceptions.ConnectionError: HTTPSConnectionPool(host='chromedriver.storage.googleapis.com', port=443): Max retries exceeded with url: /LATEST_RELEASE (Caused by NameResolutionError("<urllib3.connection.HTTPSConnection object at 0x7ff0b2cc6210>: Failed to resolve 'chromedriver.storage.googleapis.com' ([Errno -3] Temporary failure in name resolution)"))

During handling of the above exception, another exception occurred:

Traceback (most recent call last):
  File "/home/airflow/.local/lib/python3.12/site-packages/airflow/models/taskinstance.py", line 767, in _execute_task
    result = _execute_callable(context=context, **execute_callable_kwargs)
             ^^^^^^^^^^^^^^^^^^^^^^^^^^^^^^^^^^^^^^^^^^^^^^^^^^^^^^^^^^^^^
  File "/home/airflow/.local/lib/python3.12/site-packages/airflow/models/taskinstance.py", line 733, in _execute_callable
    return ExecutionCallableRunner(
           ^^^^^^^^^^^^^^^^^^^^^^^^
  File "/home/airflow/.local/lib/python3.12/site-packages/airflow/utils/operator_helpers.py", line 252, in run
    return self.func(*args, **kwargs)
           ^^^^^^^^^^^^^^^^^^^^^^^^^^
  File "/home/airflow/.local/lib/python3.12/site-packages/airflow/models/baseoperator.py", line 422, in wrapper
    return func(self, *args, **kwargs)
           ^^^^^^^^^^^^^^^^^^^^^^^^^^^
  File "/home/airflow/.local/lib/python3.12/site-packages/airflow/operators/python.py", line 238, in execute
    return_value = self.execute_callable()
                   ^^^^^^^^^^^^^^^^^^^^^^^
  File "/home/airflow/.local/lib/python3.12/site-packages/airflow/operators/python.py", line 256, in execute_callable
    return runner.run(*self.op_args, **self.op_kwargs)
           ^^^^^^^^^^^^^^^^^^^^^^^^^^^^^^^^^^^^^^^^^^^
  File "/home/airflow/.local/lib/python3.12/site-packages/airflow/utils/operator_helpers.py", line 252, in run
    return self.func(*args, **kwargs)
           ^^^^^^^^^^^^^^^^^^^^^^^^^^
  File "/opt/airflow/dags/scraping_lm.py", line 20, in scraping_etl
    driver = webdriver.Chrome(service=Service(ChromeDriverManager().install()), options=options)
                                              ^^^^^^^^^^^^^^^^^^^^^^^^^^^^^^^
  File "/home/airflow/.local/lib/python3.12/site-packages/webdriver_manager/chrome.py", line 40, in install
    driver_path = self._get_driver_binary_path(self.driver)
                  ^^^^^^^^^^^^^^^^^^^^^^^^^^^^^^^^^^^^^^^^^
  File "/home/airflow/.local/lib/python3.12/site-packages/webdriver_manager/core/manager.py", line 41, in _get_driver_binary_path
    binary_path = self._cache_manager.save_file_to_cache(driver, file)
                  ^^^^^^^^^^^^^^^^^^^^^^^^^^^^^^^^^^^^^^^^^^^^^^^^^^^^
  File "/home/airflow/.local/lib/python3.12/site-packages/webdriver_manager/core/driver_cache.py", line 52, in save_file_to_cache
    path = self.__get_path(driver)
           ^^^^^^^^^^^^^^^^^^^^^^^
  File "/home/airflow/.local/lib/python3.12/site-packages/webdriver_manager/core/driver_cache.py", line 162, in __get_path
    driver.get_driver_version_to_download(),
    ^^^^^^^^^^^^^^^^^^^^^^^^^^^^^^^^^^^^^^^
  File "/home/airflow/.local/lib/python3.12/site-packages/webdriver_manager/core/driver.py", line 48, in get_driver_version_to_download
    return self.get_latest_release_version()
           ^^^^^^^^^^^^^^^^^^^^^^^^^^^^^^^^^
  File "/home/airflow/.local/lib/python3.12/site-packages/webdriver_manager/drivers/chrome.py", line 70, in get_latest_release_version
    resp = self._http_client.get(url=latest_release_url)
           ^^^^^^^^^^^^^^^^^^^^^^^^^^^^^^^^^^^^^^^^^^^^^
  File "/home/airflow/.local/lib/python3.12/site-packages/webdriver_manager/core/http.py", line 35, in get
    raise exceptions.ConnectionError(f"Could not reach host. Are you offline?")
requests.exceptions.ConnectionError: Could not reach host. Are you offline?
[2025-01-27T06:14:45.241+0000] {taskinstance.py:340} INFO - ::group::Post task execution logs
[2025-01-27T06:14:45.260+0000] {standard_task_runner.py:124} ERROR - Failed to execute job 61 for task testing_scraping ((psycopg2.OperationalError) could not translate host name "postgres" to address: Temporary failure in name resolution

(Background on this error at: https://sqlalche.me/e/14/e3q8); 212)
Traceback (most recent call last):
  File "/home/airflow/.local/lib/python3.12/site-packages/urllib3/connection.py", line 199, in _new_conn
    sock = connection.create_connection(
           ^^^^^^^^^^^^^^^^^^^^^^^^^^^^^
  File "/home/airflow/.local/lib/python3.12/site-packages/urllib3/util/connection.py", line 60, in create_connection
    for res in socket.getaddrinfo(host, port, family, socket.SOCK_STREAM):
               ^^^^^^^^^^^^^^^^^^^^^^^^^^^^^^^^^^^^^^^^^^^^^^^^^^^^^^^^^^
  File "/usr/local/lib/python3.12/socket.py", line 976, in getaddrinfo
    for res in _socket.getaddrinfo(host, port, family, type, proto, flags):
               ^^^^^^^^^^^^^^^^^^^^^^^^^^^^^^^^^^^^^^^^^^^^^^^^^^^^^^^^^^^
socket.gaierror: [Errno -3] Temporary failure in name resolution

The above exception was the direct cause of the following exception:

Traceback (most recent call last):
  File "/home/airflow/.local/lib/python3.12/site-packages/urllib3/connectionpool.py", line 789, in urlopen
    response = self._make_request(
               ^^^^^^^^^^^^^^^^^^^
  File "/home/airflow/.local/lib/python3.12/site-packages/urllib3/connectionpool.py", line 490, in _make_request
    raise new_e
  File "/home/airflow/.local/lib/python3.12/site-packages/urllib3/connectionpool.py", line 466, in _make_request
    self._validate_conn(conn)
  File "/home/airflow/.local/lib/python3.12/site-packages/urllib3/connectionpool.py", line 1095, in _validate_conn
    conn.connect()
  File "/home/airflow/.local/lib/python3.12/site-packages/urllib3/connection.py", line 693, in connect
    self.sock = sock = self._new_conn()
                       ^^^^^^^^^^^^^^^^
  File "/home/airflow/.local/lib/python3.12/site-packages/urllib3/connection.py", line 206, in _new_conn
    raise NameResolutionError(self.host, self, e) from e
urllib3.exceptions.NameResolutionError: <urllib3.connection.HTTPSConnection object at 0x7ff0b2cc6210>: Failed to resolve 'chromedriver.storage.googleapis.com' ([Errno -3] Temporary failure in name resolution)

The above exception was the direct cause of the following exception:

Traceback (most recent call last):
  File "/home/airflow/.local/lib/python3.12/site-packages/requests/adapters.py", line 667, in send
    resp = conn.urlopen(
           ^^^^^^^^^^^^^
  File "/home/airflow/.local/lib/python3.12/site-packages/urllib3/connectionpool.py", line 843, in urlopen
    retries = retries.increment(
              ^^^^^^^^^^^^^^^^^^
  File "/home/airflow/.local/lib/python3.12/site-packages/urllib3/util/retry.py", line 519, in increment
    raise MaxRetryError(_pool, url, reason) from reason  # type: ignore[arg-type]
    ^^^^^^^^^^^^^^^^^^^^^^^^^^^^^^^^^^^^^^^^^^^^^^^^^^^
urllib3.exceptions.MaxRetryError: HTTPSConnectionPool(host='chromedriver.storage.googleapis.com', port=443): Max retries exceeded with url: /LATEST_RELEASE (Caused by NameResolutionError("<urllib3.connection.HTTPSConnection object at 0x7ff0b2cc6210>: Failed to resolve 'chromedriver.storage.googleapis.com' ([Errno -3] Temporary failure in name resolution)"))

During handling of the above exception, another exception occurred:

Traceback (most recent call last):
  File "/home/airflow/.local/lib/python3.12/site-packages/webdriver_manager/core/http.py", line 32, in get
    resp = requests.get(
           ^^^^^^^^^^^^^
  File "/home/airflow/.local/lib/python3.12/site-packages/requests/api.py", line 73, in get
    return request("get", url, params=params, **kwargs)
           ^^^^^^^^^^^^^^^^^^^^^^^^^^^^^^^^^^^^^^^^^^^^
  File "/home/airflow/.local/lib/python3.12/site-packages/requests/api.py", line 59, in request
    return session.request(method=method, url=url, **kwargs)
           ^^^^^^^^^^^^^^^^^^^^^^^^^^^^^^^^^^^^^^^^^^^^^^^^^
  File "/home/airflow/.local/lib/python3.12/site-packages/requests/sessions.py", line 589, in request
    resp = self.send(prep, **send_kwargs)
           ^^^^^^^^^^^^^^^^^^^^^^^^^^^^^^
  File "/home/airflow/.local/lib/python3.12/site-packages/requests/sessions.py", line 703, in send
    r = adapter.send(request, **kwargs)
        ^^^^^^^^^^^^^^^^^^^^^^^^^^^^^^^
  File "/home/airflow/.local/lib/python3.12/site-packages/requests/adapters.py", line 700, in send
    raise ConnectionError(e, request=request)
requests.exceptions.ConnectionError: HTTPSConnectionPool(host='chromedriver.storage.googleapis.com', port=443): Max retries exceeded with url: /LATEST_RELEASE (Caused by NameResolutionError("<urllib3.connection.HTTPSConnection object at 0x7ff0b2cc6210>: Failed to resolve 'chromedriver.storage.googleapis.com' ([Errno -3] Temporary failure in name resolution)"))

During handling of the above exception, another exception occurred:

Traceback (most recent call last):
  File "/home/airflow/.local/lib/python3.12/site-packages/airflow/models/taskinstance.py", line 273, in _run_raw_task
    TaskInstance._execute_task_with_callbacks(
  File "/home/airflow/.local/lib/python3.12/site-packages/airflow/models/taskinstance.py", line 3159, in _execute_task_with_callbacks
    result = self._execute_task(context, task_orig)
             ^^^^^^^^^^^^^^^^^^^^^^^^^^^^^^^^^^^^^^
  File "/home/airflow/.local/lib/python3.12/site-packages/airflow/models/taskinstance.py", line 3183, in _execute_task
    return _execute_task(self, context, task_orig)
           ^^^^^^^^^^^^^^^^^^^^^^^^^^^^^^^^^^^^^^^
  File "/home/airflow/.local/lib/python3.12/site-packages/airflow/models/taskinstance.py", line 767, in _execute_task
    result = _execute_callable(context=context, **execute_callable_kwargs)
             ^^^^^^^^^^^^^^^^^^^^^^^^^^^^^^^^^^^^^^^^^^^^^^^^^^^^^^^^^^^^^
  File "/home/airflow/.local/lib/python3.12/site-packages/airflow/models/taskinstance.py", line 733, in _execute_callable
    return ExecutionCallableRunner(
           ^^^^^^^^^^^^^^^^^^^^^^^^
  File "/home/airflow/.local/lib/python3.12/site-packages/airflow/utils/operator_helpers.py", line 252, in run
    return self.func(*args, **kwargs)
           ^^^^^^^^^^^^^^^^^^^^^^^^^^
  File "/home/airflow/.local/lib/python3.12/site-packages/airflow/models/baseoperator.py", line 422, in wrapper
    return func(self, *args, **kwargs)
           ^^^^^^^^^^^^^^^^^^^^^^^^^^^
  File "/home/airflow/.local/lib/python3.12/site-packages/airflow/operators/python.py", line 238, in execute
    return_value = self.execute_callable()
                   ^^^^^^^^^^^^^^^^^^^^^^^
  File "/home/airflow/.local/lib/python3.12/site-packages/airflow/operators/python.py", line 256, in execute_callable
    return runner.run(*self.op_args, **self.op_kwargs)
           ^^^^^^^^^^^^^^^^^^^^^^^^^^^^^^^^^^^^^^^^^^^
  File "/home/airflow/.local/lib/python3.12/site-packages/airflow/utils/operator_helpers.py", line 252, in run
    return self.func(*args, **kwargs)
           ^^^^^^^^^^^^^^^^^^^^^^^^^^
  File "/opt/airflow/dags/scraping_lm.py", line 20, in scraping_etl
    driver = webdriver.Chrome(service=Service(ChromeDriverManager().install()), options=options)
                                              ^^^^^^^^^^^^^^^^^^^^^^^^^^^^^^^
  File "/home/airflow/.local/lib/python3.12/site-packages/webdriver_manager/chrome.py", line 40, in install
    driver_path = self._get_driver_binary_path(self.driver)
                  ^^^^^^^^^^^^^^^^^^^^^^^^^^^^^^^^^^^^^^^^^
  File "/home/airflow/.local/lib/python3.12/site-packages/webdriver_manager/core/manager.py", line 41, in _get_driver_binary_path
    binary_path = self._cache_manager.save_file_to_cache(driver, file)
                  ^^^^^^^^^^^^^^^^^^^^^^^^^^^^^^^^^^^^^^^^^^^^^^^^^^^^
  File "/home/airflow/.local/lib/python3.12/site-packages/webdriver_manager/core/driver_cache.py", line 52, in save_file_to_cache
    path = self.__get_path(driver)
           ^^^^^^^^^^^^^^^^^^^^^^^
  File "/home/airflow/.local/lib/python3.12/site-packages/webdriver_manager/core/driver_cache.py", line 162, in __get_path
    driver.get_driver_version_to_download(),
    ^^^^^^^^^^^^^^^^^^^^^^^^^^^^^^^^^^^^^^^
  File "/home/airflow/.local/lib/python3.12/site-packages/webdriver_manager/core/driver.py", line 48, in get_driver_version_to_download
    return self.get_latest_release_version()
           ^^^^^^^^^^^^^^^^^^^^^^^^^^^^^^^^^
  File "/home/airflow/.local/lib/python3.12/site-packages/webdriver_manager/drivers/chrome.py", line 70, in get_latest_release_version
    resp = self._http_client.get(url=latest_release_url)
           ^^^^^^^^^^^^^^^^^^^^^^^^^^^^^^^^^^^^^^^^^^^^^
  File "/home/airflow/.local/lib/python3.12/site-packages/webdriver_manager/core/http.py", line 35, in get
    raise exceptions.ConnectionError(f"Could not reach host. Are you offline?")
requests.exceptions.ConnectionError: Could not reach host. Are you offline?

During handling of the above exception, another exception occurred:

Traceback (most recent call last):
  File "/home/airflow/.local/lib/python3.12/site-packages/sqlalchemy/engine/base.py", line 3371, in _wrap_pool_connect
    return fn()
           ^^^^
  File "/home/airflow/.local/lib/python3.12/site-packages/sqlalchemy/pool/base.py", line 327, in connect
    return _ConnectionFairy._checkout(self)
           ^^^^^^^^^^^^^^^^^^^^^^^^^^^^^^^^
  File "/home/airflow/.local/lib/python3.12/site-packages/sqlalchemy/pool/base.py", line 894, in _checkout
    fairy = _ConnectionRecord.checkout(pool)
            ^^^^^^^^^^^^^^^^^^^^^^^^^^^^^^^^
  File "/home/airflow/.local/lib/python3.12/site-packages/sqlalchemy/pool/base.py", line 493, in checkout
    rec = pool._do_get()
          ^^^^^^^^^^^^^^
  File "/home/airflow/.local/lib/python3.12/site-packages/sqlalchemy/pool/impl.py", line 256, in _do_get
    return self._create_connection()
           ^^^^^^^^^^^^^^^^^^^^^^^^^
  File "/home/airflow/.local/lib/python3.12/site-packages/sqlalchemy/pool/base.py", line 273, in _create_connection
    return _ConnectionRecord(self)
           ^^^^^^^^^^^^^^^^^^^^^^^
  File "/home/airflow/.local/lib/python3.12/site-packages/sqlalchemy/pool/base.py", line 388, in __init__
    self.__connect()
  File "/home/airflow/.local/lib/python3.12/site-packages/sqlalchemy/pool/base.py", line 690, in __connect
    with util.safe_reraise():
         ^^^^^^^^^^^^^^^^^^^
  File "/home/airflow/.local/lib/python3.12/site-packages/sqlalchemy/util/langhelpers.py", line 70, in __exit__
    compat.raise_(
  File "/home/airflow/.local/lib/python3.12/site-packages/sqlalchemy/util/compat.py", line 211, in raise_
    raise exception
  File "/home/airflow/.local/lib/python3.12/site-packages/sqlalchemy/pool/base.py", line 686, in __connect
    self.dbapi_connection = connection = pool._invoke_creator(self)
                                         ^^^^^^^^^^^^^^^^^^^^^^^^^^
  File "/home/airflow/.local/lib/python3.12/site-packages/sqlalchemy/engine/create.py", line 574, in connect
    return dialect.connect(*cargs, **cparams)
           ^^^^^^^^^^^^^^^^^^^^^^^^^^^^^^^^^^
  File "/home/airflow/.local/lib/python3.12/site-packages/sqlalchemy/engine/default.py", line 598, in connect
    return self.dbapi.connect(*cargs, **cparams)
           ^^^^^^^^^^^^^^^^^^^^^^^^^^^^^^^^^^^^^
  File "/home/airflow/.local/lib/python3.12/site-packages/psycopg2/__init__.py", line 122, in connect
    conn = _connect(dsn, connection_factory=connection_factory, **kwasync)
           ^^^^^^^^^^^^^^^^^^^^^^^^^^^^^^^^^^^^^^^^^^^^^^^^^^^^^^^^^^^^^^^
psycopg2.OperationalError: could not translate host name "postgres" to address: Temporary failure in name resolution


The above exception was the direct cause of the following exception:

Traceback (most recent call last):
  File "/home/airflow/.local/lib/python3.12/site-packages/airflow/task/task_runner/standard_task_runner.py", line 117, in _start_by_fork
    ret = args.func(args, dag=self.dag)
          ^^^^^^^^^^^^^^^^^^^^^^^^^^^^^
  File "/home/airflow/.local/lib/python3.12/site-packages/airflow/cli/cli_config.py", line 49, in command
    return func(*args, **kwargs)
           ^^^^^^^^^^^^^^^^^^^^^
  File "/home/airflow/.local/lib/python3.12/site-packages/airflow/utils/cli.py", line 116, in wrapper
    return f(*args, **kwargs)
           ^^^^^^^^^^^^^^^^^^
  File "/home/airflow/.local/lib/python3.12/site-packages/airflow/cli/commands/task_command.py", line 483, in task_run
    task_return_code = _run_task_by_selected_method(args, _dag, ti)
                       ^^^^^^^^^^^^^^^^^^^^^^^^^^^^^^^^^^^^^^^^^^^^
  File "/home/airflow/.local/lib/python3.12/site-packages/airflow/cli/commands/task_command.py", line 256, in _run_task_by_selected_method
    return _run_raw_task(args, ti)
           ^^^^^^^^^^^^^^^^^^^^^^^
  File "/home/airflow/.local/lib/python3.12/site-packages/airflow/cli/commands/task_command.py", line 341, in _run_raw_task
    return ti._run_raw_task(
           ^^^^^^^^^^^^^^^^^
  File "/home/airflow/.local/lib/python3.12/site-packages/airflow/utils/session.py", line 97, in wrapper
    return func(*args, session=session, **kwargs)
           ^^^^^^^^^^^^^^^^^^^^^^^^^^^^^^^^^^^^^^
  File "/home/airflow/.local/lib/python3.12/site-packages/airflow/models/taskinstance.py", line 3005, in _run_raw_task
    return _run_raw_task(
           ^^^^^^^^^^^^^^
  File "/home/airflow/.local/lib/python3.12/site-packages/airflow/models/taskinstance.py", line 336, in _run_raw_task
    ti.handle_failure(e, test_mode, context, session=session)
  File "/home/airflow/.local/lib/python3.12/site-packages/airflow/utils/session.py", line 94, in wrapper
    return func(*args, **kwargs)
           ^^^^^^^^^^^^^^^^^^^^^
  File "/home/airflow/.local/lib/python3.12/site-packages/airflow/models/taskinstance.py", line 3428, in handle_failure
    _handle_failure(
  File "/home/airflow/.local/lib/python3.12/site-packages/airflow/utils/session.py", line 94, in wrapper
    return func(*args, **kwargs)
           ^^^^^^^^^^^^^^^^^^^^^
  File "/home/airflow/.local/lib/python3.12/site-packages/airflow/api_internal/internal_api_call.py", line 166, in wrapper
    return func(*args, **kwargs)
           ^^^^^^^^^^^^^^^^^^^^^
  File "/home/airflow/.local/lib/python3.12/site-packages/airflow/models/taskinstance.py", line 1215, in _handle_failure
    failure_context = TaskInstance.fetch_handle_failure_context(
                      ^^^^^^^^^^^^^^^^^^^^^^^^^^^^^^^^^^^^^^^^^^
  File "/home/airflow/.local/lib/python3.12/site-packages/airflow/models/taskinstance.py", line 3315, in fetch_handle_failure_context
    ti.refresh_from_db(session)
  File "/home/airflow/.local/lib/python3.12/site-packages/airflow/utils/session.py", line 94, in wrapper
    return func(*args, **kwargs)
           ^^^^^^^^^^^^^^^^^^^^^
  File "/home/airflow/.local/lib/python3.12/site-packages/airflow/models/taskinstance.py", line 2359, in refresh_from_db
    _refresh_from_db(task_instance=self, session=session, lock_for_update=lock_for_update)
  File "/home/airflow/.local/lib/python3.12/site-packages/airflow/models/taskinstance.py", line 872, in _refresh_from_db
    ti = TaskInstance.get_task_instance(
         ^^^^^^^^^^^^^^^^^^^^^^^^^^^^^^^
  File "/home/airflow/.local/lib/python3.12/site-packages/airflow/api_internal/internal_api_call.py", line 166, in wrapper
    return func(*args, **kwargs)
           ^^^^^^^^^^^^^^^^^^^^^
  File "/home/airflow/.local/lib/python3.12/site-packages/airflow/utils/session.py", line 94, in wrapper
    return func(*args, **kwargs)
           ^^^^^^^^^^^^^^^^^^^^^
  File "/home/airflow/.local/lib/python3.12/site-packages/airflow/models/taskinstance.py", line 2345, in get_task_instance
    return query.one_or_none()
           ^^^^^^^^^^^^^^^^^^^
  File "/home/airflow/.local/lib/python3.12/site-packages/sqlalchemy/orm/query.py", line 2850, in one_or_none
    return self._iter().one_or_none()
           ^^^^^^^^^^^^
  File "/home/airflow/.local/lib/python3.12/site-packages/sqlalchemy/orm/query.py", line 2916, in _iter
    result = self.session.execute(
             ^^^^^^^^^^^^^^^^^^^^^
  File "/home/airflow/.local/lib/python3.12/site-packages/sqlalchemy/orm/session.py", line 1716, in execute
    conn = self._connection_for_bind(bind)
           ^^^^^^^^^^^^^^^^^^^^^^^^^^^^^^^
  File "/home/airflow/.local/lib/python3.12/site-packages/sqlalchemy/orm/session.py", line 1555, in _connection_for_bind
    return self._transaction._connection_for_bind(
           ^^^^^^^^^^^^^^^^^^^^^^^^^^^^^^^^^^^^^^^
  File "/home/airflow/.local/lib/python3.12/site-packages/sqlalchemy/orm/session.py", line 750, in _connection_for_bind
    conn = bind.connect()
           ^^^^^^^^^^^^^^
  File "/home/airflow/.local/lib/python3.12/site-packages/sqlalchemy/future/engine.py", line 412, in connect
    return super(Engine, self).connect()
           ^^^^^^^^^^^^^^^^^^^^^^^^^^^^^
  File "/home/airflow/.local/lib/python3.12/site-packages/sqlalchemy/engine/base.py", line 3325, in connect
    return self._connection_cls(self, close_with_result=close_with_result)
           ^^^^^^^^^^^^^^^^^^^^^^^^^^^^^^^^^^^^^^^^^^^^^^^^^^^^^^^^^^^^^^^
  File "/home/airflow/.local/lib/python3.12/site-packages/sqlalchemy/engine/base.py", line 96, in __init__
    else engine.raw_connection()
         ^^^^^^^^^^^^^^^^^^^^^^^
  File "/home/airflow/.local/lib/python3.12/site-packages/sqlalchemy/engine/base.py", line 3404, in raw_connection
    return self._wrap_pool_connect(self.pool.connect, _connection)
           ^^^^^^^^^^^^^^^^^^^^^^^^^^^^^^^^^^^^^^^^^^^^^^^^^^^^^^^
  File "/home/airflow/.local/lib/python3.12/site-packages/sqlalchemy/engine/base.py", line 3374, in _wrap_pool_connect
    Connection._handle_dbapi_exception_noconnection(
  File "/home/airflow/.local/lib/python3.12/site-packages/sqlalchemy/engine/base.py", line 2208, in _handle_dbapi_exception_noconnection
    util.raise_(
  File "/home/airflow/.local/lib/python3.12/site-packages/sqlalchemy/util/compat.py", line 211, in raise_
    raise exception
  File "/home/airflow/.local/lib/python3.12/site-packages/sqlalchemy/engine/base.py", line 3371, in _wrap_pool_connect
    return fn()
           ^^^^
  File "/home/airflow/.local/lib/python3.12/site-packages/sqlalchemy/pool/base.py", line 327, in connect
    return _ConnectionFairy._checkout(self)
           ^^^^^^^^^^^^^^^^^^^^^^^^^^^^^^^^
  File "/home/airflow/.local/lib/python3.12/site-packages/sqlalchemy/pool/base.py", line 894, in _checkout
    fairy = _ConnectionRecord.checkout(pool)
            ^^^^^^^^^^^^^^^^^^^^^^^^^^^^^^^^
  File "/home/airflow/.local/lib/python3.12/site-packages/sqlalchemy/pool/base.py", line 493, in checkout
    rec = pool._do_get()
          ^^^^^^^^^^^^^^
  File "/home/airflow/.local/lib/python3.12/site-packages/sqlalchemy/pool/impl.py", line 256, in _do_get
    return self._create_connection()
           ^^^^^^^^^^^^^^^^^^^^^^^^^
  File "/home/airflow/.local/lib/python3.12/site-packages/sqlalchemy/pool/base.py", line 273, in _create_connection
    return _ConnectionRecord(self)
           ^^^^^^^^^^^^^^^^^^^^^^^
  File "/home/airflow/.local/lib/python3.12/site-packages/sqlalchemy/pool/base.py", line 388, in __init__
    self.__connect()
  File "/home/airflow/.local/lib/python3.12/site-packages/sqlalchemy/pool/base.py", line 690, in __connect
    with util.safe_reraise():
         ^^^^^^^^^^^^^^^^^^^
  File "/home/airflow/.local/lib/python3.12/site-packages/sqlalchemy/util/langhelpers.py", line 70, in __exit__
    compat.raise_(
  File "/home/airflow/.local/lib/python3.12/site-packages/sqlalchemy/util/compat.py", line 211, in raise_
    raise exception
  File "/home/airflow/.local/lib/python3.12/site-packages/sqlalchemy/pool/base.py", line 686, in __connect
    self.dbapi_connection = connection = pool._invoke_creator(self)
                                         ^^^^^^^^^^^^^^^^^^^^^^^^^^
  File "/home/airflow/.local/lib/python3.12/site-packages/sqlalchemy/engine/create.py", line 574, in connect
    return dialect.connect(*cargs, **cparams)
           ^^^^^^^^^^^^^^^^^^^^^^^^^^^^^^^^^^
  File "/home/airflow/.local/lib/python3.12/site-packages/sqlalchemy/engine/default.py", line 598, in connect
    return self.dbapi.connect(*cargs, **cparams)
           ^^^^^^^^^^^^^^^^^^^^^^^^^^^^^^^^^^^^^
  File "/home/airflow/.local/lib/python3.12/site-packages/psycopg2/__init__.py", line 122, in connect
    conn = _connect(dsn, connection_factory=connection_factory, **kwasync)
           ^^^^^^^^^^^^^^^^^^^^^^^^^^^^^^^^^^^^^^^^^^^^^^^^^^^^^^^^^^^^^^^
sqlalchemy.exc.OperationalError: (psycopg2.OperationalError) could not translate host name "postgres" to address: Temporary failure in name resolution

(Background on this error at: https://sqlalche.me/e/14/e3q8)
[2025-01-27T06:14:49.171+0000] {job.py:229} INFO - Heartbeat recovered after 26.19 seconds
[2025-01-27T06:14:59.232+0000] {job.py:239} ERROR - Job heartbeat failed with error
Traceback (most recent call last):
  File "/home/airflow/.local/lib/python3.12/site-packages/sqlalchemy/engine/base.py", line 3371, in _wrap_pool_connect
    return fn()
           ^^^^
  File "/home/airflow/.local/lib/python3.12/site-packages/sqlalchemy/pool/base.py", line 327, in connect
    return _ConnectionFairy._checkout(self)
           ^^^^^^^^^^^^^^^^^^^^^^^^^^^^^^^^
  File "/home/airflow/.local/lib/python3.12/site-packages/sqlalchemy/pool/base.py", line 894, in _checkout
    fairy = _ConnectionRecord.checkout(pool)
            ^^^^^^^^^^^^^^^^^^^^^^^^^^^^^^^^
  File "/home/airflow/.local/lib/python3.12/site-packages/sqlalchemy/pool/base.py", line 493, in checkout
    rec = pool._do_get()
          ^^^^^^^^^^^^^^
  File "/home/airflow/.local/lib/python3.12/site-packages/sqlalchemy/pool/impl.py", line 256, in _do_get
    return self._create_connection()
           ^^^^^^^^^^^^^^^^^^^^^^^^^
  File "/home/airflow/.local/lib/python3.12/site-packages/sqlalchemy/pool/base.py", line 273, in _create_connection
    return _ConnectionRecord(self)
           ^^^^^^^^^^^^^^^^^^^^^^^
  File "/home/airflow/.local/lib/python3.12/site-packages/sqlalchemy/pool/base.py", line 388, in __init__
    self.__connect()
  File "/home/airflow/.local/lib/python3.12/site-packages/sqlalchemy/pool/base.py", line 690, in __connect
    with util.safe_reraise():
         ^^^^^^^^^^^^^^^^^^^
  File "/home/airflow/.local/lib/python3.12/site-packages/sqlalchemy/util/langhelpers.py", line 70, in __exit__
    compat.raise_(
  File "/home/airflow/.local/lib/python3.12/site-packages/sqlalchemy/util/compat.py", line 211, in raise_
    raise exception
  File "/home/airflow/.local/lib/python3.12/site-packages/sqlalchemy/pool/base.py", line 686, in __connect
    self.dbapi_connection = connection = pool._invoke_creator(self)
                                         ^^^^^^^^^^^^^^^^^^^^^^^^^^
  File "/home/airflow/.local/lib/python3.12/site-packages/sqlalchemy/engine/create.py", line 574, in connect
    return dialect.connect(*cargs, **cparams)
           ^^^^^^^^^^^^^^^^^^^^^^^^^^^^^^^^^^
  File "/home/airflow/.local/lib/python3.12/site-packages/sqlalchemy/engine/default.py", line 598, in connect
    return self.dbapi.connect(*cargs, **cparams)
           ^^^^^^^^^^^^^^^^^^^^^^^^^^^^^^^^^^^^^
  File "/home/airflow/.local/lib/python3.12/site-packages/psycopg2/__init__.py", line 122, in connect
    conn = _connect(dsn, connection_factory=connection_factory, **kwasync)
           ^^^^^^^^^^^^^^^^^^^^^^^^^^^^^^^^^^^^^^^^^^^^^^^^^^^^^^^^^^^^^^^
psycopg2.OperationalError: could not translate host name "postgres" to address: Temporary failure in name resolution


The above exception was the direct cause of the following exception:

Traceback (most recent call last):
  File "/home/airflow/.local/lib/python3.12/site-packages/airflow/jobs/job.py", line 233, in heartbeat
    heartbeat_callback(session)
  File "/home/airflow/.local/lib/python3.12/site-packages/airflow/utils/session.py", line 94, in wrapper
    return func(*args, **kwargs)
           ^^^^^^^^^^^^^^^^^^^^^
  File "/home/airflow/.local/lib/python3.12/site-packages/airflow/jobs/local_task_job_runner.py", line 284, in heartbeat_callback
    self.task_instance.refresh_from_db()
  File "/home/airflow/.local/lib/python3.12/site-packages/airflow/utils/session.py", line 97, in wrapper
    return func(*args, session=session, **kwargs)
           ^^^^^^^^^^^^^^^^^^^^^^^^^^^^^^^^^^^^^^
  File "/home/airflow/.local/lib/python3.12/site-packages/airflow/models/taskinstance.py", line 2359, in refresh_from_db
    _refresh_from_db(task_instance=self, session=session, lock_for_update=lock_for_update)
  File "/home/airflow/.local/lib/python3.12/site-packages/airflow/models/taskinstance.py", line 872, in _refresh_from_db
    ti = TaskInstance.get_task_instance(
         ^^^^^^^^^^^^^^^^^^^^^^^^^^^^^^^
  File "/home/airflow/.local/lib/python3.12/site-packages/airflow/api_internal/internal_api_call.py", line 166, in wrapper
    return func(*args, **kwargs)
           ^^^^^^^^^^^^^^^^^^^^^
  File "/home/airflow/.local/lib/python3.12/site-packages/airflow/utils/session.py", line 94, in wrapper
    return func(*args, **kwargs)
           ^^^^^^^^^^^^^^^^^^^^^
  File "/home/airflow/.local/lib/python3.12/site-packages/airflow/models/taskinstance.py", line 2345, in get_task_instance
    return query.one_or_none()
           ^^^^^^^^^^^^^^^^^^^
  File "/home/airflow/.local/lib/python3.12/site-packages/sqlalchemy/orm/query.py", line 2850, in one_or_none
    return self._iter().one_or_none()
           ^^^^^^^^^^^^
  File "/home/airflow/.local/lib/python3.12/site-packages/sqlalchemy/orm/query.py", line 2916, in _iter
    result = self.session.execute(
             ^^^^^^^^^^^^^^^^^^^^^
  File "/home/airflow/.local/lib/python3.12/site-packages/sqlalchemy/orm/session.py", line 1716, in execute
    conn = self._connection_for_bind(bind)
           ^^^^^^^^^^^^^^^^^^^^^^^^^^^^^^^
  File "/home/airflow/.local/lib/python3.12/site-packages/sqlalchemy/orm/session.py", line 1555, in _connection_for_bind
    return self._transaction._connection_for_bind(
           ^^^^^^^^^^^^^^^^^^^^^^^^^^^^^^^^^^^^^^^
  File "/home/airflow/.local/lib/python3.12/site-packages/sqlalchemy/orm/session.py", line 750, in _connection_for_bind
    conn = bind.connect()
           ^^^^^^^^^^^^^^
  File "/home/airflow/.local/lib/python3.12/site-packages/sqlalchemy/future/engine.py", line 412, in connect
    return super(Engine, self).connect()
           ^^^^^^^^^^^^^^^^^^^^^^^^^^^^^
  File "/home/airflow/.local/lib/python3.12/site-packages/sqlalchemy/engine/base.py", line 3325, in connect
    return self._connection_cls(self, close_with_result=close_with_result)
           ^^^^^^^^^^^^^^^^^^^^^^^^^^^^^^^^^^^^^^^^^^^^^^^^^^^^^^^^^^^^^^^
  File "/home/airflow/.local/lib/python3.12/site-packages/sqlalchemy/engine/base.py", line 96, in __init__
    else engine.raw_connection()
         ^^^^^^^^^^^^^^^^^^^^^^^
  File "/home/airflow/.local/lib/python3.12/site-packages/sqlalchemy/engine/base.py", line 3404, in raw_connection
    return self._wrap_pool_connect(self.pool.connect, _connection)
           ^^^^^^^^^^^^^^^^^^^^^^^^^^^^^^^^^^^^^^^^^^^^^^^^^^^^^^^
  File "/home/airflow/.local/lib/python3.12/site-packages/sqlalchemy/engine/base.py", line 3374, in _wrap_pool_connect
    Connection._handle_dbapi_exception_noconnection(
  File "/home/airflow/.local/lib/python3.12/site-packages/sqlalchemy/engine/base.py", line 2208, in _handle_dbapi_exception_noconnection
    util.raise_(
  File "/home/airflow/.local/lib/python3.12/site-packages/sqlalchemy/util/compat.py", line 211, in raise_
    raise exception
  File "/home/airflow/.local/lib/python3.12/site-packages/sqlalchemy/engine/base.py", line 3371, in _wrap_pool_connect
    return fn()
           ^^^^
  File "/home/airflow/.local/lib/python3.12/site-packages/sqlalchemy/pool/base.py", line 327, in connect
    return _ConnectionFairy._checkout(self)
           ^^^^^^^^^^^^^^^^^^^^^^^^^^^^^^^^
  File "/home/airflow/.local/lib/python3.12/site-packages/sqlalchemy/pool/base.py", line 894, in _checkout
    fairy = _ConnectionRecord.checkout(pool)
            ^^^^^^^^^^^^^^^^^^^^^^^^^^^^^^^^
  File "/home/airflow/.local/lib/python3.12/site-packages/sqlalchemy/pool/base.py", line 493, in checkout
    rec = pool._do_get()
          ^^^^^^^^^^^^^^
  File "/home/airflow/.local/lib/python3.12/site-packages/sqlalchemy/pool/impl.py", line 256, in _do_get
    return self._create_connection()
           ^^^^^^^^^^^^^^^^^^^^^^^^^
  File "/home/airflow/.local/lib/python3.12/site-packages/sqlalchemy/pool/base.py", line 273, in _create_connection
    return _ConnectionRecord(self)
           ^^^^^^^^^^^^^^^^^^^^^^^
  File "/home/airflow/.local/lib/python3.12/site-packages/sqlalchemy/pool/base.py", line 388, in __init__
    self.__connect()
  File "/home/airflow/.local/lib/python3.12/site-packages/sqlalchemy/pool/base.py", line 690, in __connect
    with util.safe_reraise():
         ^^^^^^^^^^^^^^^^^^^
  File "/home/airflow/.local/lib/python3.12/site-packages/sqlalchemy/util/langhelpers.py", line 70, in __exit__
    compat.raise_(
  File "/home/airflow/.local/lib/python3.12/site-packages/sqlalchemy/util/compat.py", line 211, in raise_
    raise exception
  File "/home/airflow/.local/lib/python3.12/site-packages/sqlalchemy/pool/base.py", line 686, in __connect
    self.dbapi_connection = connection = pool._invoke_creator(self)
                                         ^^^^^^^^^^^^^^^^^^^^^^^^^^
  File "/home/airflow/.local/lib/python3.12/site-packages/sqlalchemy/engine/create.py", line 574, in connect
    return dialect.connect(*cargs, **cparams)
           ^^^^^^^^^^^^^^^^^^^^^^^^^^^^^^^^^^
  File "/home/airflow/.local/lib/python3.12/site-packages/sqlalchemy/engine/default.py", line 598, in connect
    return self.dbapi.connect(*cargs, **cparams)
           ^^^^^^^^^^^^^^^^^^^^^^^^^^^^^^^^^^^^^
  File "/home/airflow/.local/lib/python3.12/site-packages/psycopg2/__init__.py", line 122, in connect
    conn = _connect(dsn, connection_factory=connection_factory, **kwasync)
           ^^^^^^^^^^^^^^^^^^^^^^^^^^^^^^^^^^^^^^^^^^^^^^^^^^^^^^^^^^^^^^^
sqlalchemy.exc.OperationalError: (psycopg2.OperationalError) could not translate host name "postgres" to address: Temporary failure in name resolution

(Background on this error at: https://sqlalche.me/e/14/e3q8)
[2025-01-27T06:14:59.447+0000] {job.py:245} ERROR - Job heartbeat failed with error. Scheduler may go into unhealthy state
[2025-01-27T06:14:59.478+0000] {local_task_job_runner.py:266} INFO - Task exited with return code 1
[2025-01-27T06:15:01.416+0000] {standard_task_runner.py:217} INFO - Process not found (most likely exited), stop collecting metrics
[2025-01-27T06:15:09.564+0000] {taskinstance.py:3901} WARNING - Skipping mini scheduling run due to exception: None
Traceback (most recent call last):
  File "/home/airflow/.local/lib/python3.12/site-packages/sqlalchemy/engine/base.py", line 3371, in _wrap_pool_connect
    return fn()
           ^^^^
  File "/home/airflow/.local/lib/python3.12/site-packages/sqlalchemy/pool/base.py", line 327, in connect
    return _ConnectionFairy._checkout(self)
           ^^^^^^^^^^^^^^^^^^^^^^^^^^^^^^^^
  File "/home/airflow/.local/lib/python3.12/site-packages/sqlalchemy/pool/base.py", line 894, in _checkout
    fairy = _ConnectionRecord.checkout(pool)
            ^^^^^^^^^^^^^^^^^^^^^^^^^^^^^^^^
  File "/home/airflow/.local/lib/python3.12/site-packages/sqlalchemy/pool/base.py", line 493, in checkout
    rec = pool._do_get()
          ^^^^^^^^^^^^^^
  File "/home/airflow/.local/lib/python3.12/site-packages/sqlalchemy/pool/impl.py", line 256, in _do_get
    return self._create_connection()
           ^^^^^^^^^^^^^^^^^^^^^^^^^
  File "/home/airflow/.local/lib/python3.12/site-packages/sqlalchemy/pool/base.py", line 273, in _create_connection
    return _ConnectionRecord(self)
           ^^^^^^^^^^^^^^^^^^^^^^^
  File "/home/airflow/.local/lib/python3.12/site-packages/sqlalchemy/pool/base.py", line 388, in __init__
    self.__connect()
  File "/home/airflow/.local/lib/python3.12/site-packages/sqlalchemy/pool/base.py", line 690, in __connect
    with util.safe_reraise():
         ^^^^^^^^^^^^^^^^^^^
  File "/home/airflow/.local/lib/python3.12/site-packages/sqlalchemy/util/langhelpers.py", line 70, in __exit__
    compat.raise_(
  File "/home/airflow/.local/lib/python3.12/site-packages/sqlalchemy/util/compat.py", line 211, in raise_
    raise exception
  File "/home/airflow/.local/lib/python3.12/site-packages/sqlalchemy/pool/base.py", line 686, in __connect
    self.dbapi_connection = connection = pool._invoke_creator(self)
                                         ^^^^^^^^^^^^^^^^^^^^^^^^^^
  File "/home/airflow/.local/lib/python3.12/site-packages/sqlalchemy/engine/create.py", line 574, in connect
    return dialect.connect(*cargs, **cparams)
           ^^^^^^^^^^^^^^^^^^^^^^^^^^^^^^^^^^
  File "/home/airflow/.local/lib/python3.12/site-packages/sqlalchemy/engine/default.py", line 598, in connect
    return self.dbapi.connect(*cargs, **cparams)
           ^^^^^^^^^^^^^^^^^^^^^^^^^^^^^^^^^^^^^
  File "/home/airflow/.local/lib/python3.12/site-packages/psycopg2/__init__.py", line 122, in connect
    conn = _connect(dsn, connection_factory=connection_factory, **kwasync)
           ^^^^^^^^^^^^^^^^^^^^^^^^^^^^^^^^^^^^^^^^^^^^^^^^^^^^^^^^^^^^^^^
psycopg2.OperationalError: could not translate host name "postgres" to address: Temporary failure in name resolution


The above exception was the direct cause of the following exception:

Traceback (most recent call last):
  File "/home/airflow/.local/lib/python3.12/site-packages/airflow/models/taskinstance.py", line 3856, in _schedule_downstream_tasks
    ).one_or_none()
      ^^^^^^^^^^^^^
  File "/home/airflow/.local/lib/python3.12/site-packages/sqlalchemy/orm/query.py", line 2850, in one_or_none
    return self._iter().one_or_none()
           ^^^^^^^^^^^^
  File "/home/airflow/.local/lib/python3.12/site-packages/sqlalchemy/orm/query.py", line 2916, in _iter
    result = self.session.execute(
             ^^^^^^^^^^^^^^^^^^^^^
  File "/home/airflow/.local/lib/python3.12/site-packages/sqlalchemy/orm/session.py", line 1716, in execute
    conn = self._connection_for_bind(bind)
           ^^^^^^^^^^^^^^^^^^^^^^^^^^^^^^^
  File "/home/airflow/.local/lib/python3.12/site-packages/sqlalchemy/orm/session.py", line 1555, in _connection_for_bind
    return self._transaction._connection_for_bind(
           ^^^^^^^^^^^^^^^^^^^^^^^^^^^^^^^^^^^^^^^
  File "/home/airflow/.local/lib/python3.12/site-packages/sqlalchemy/orm/session.py", line 750, in _connection_for_bind
    conn = bind.connect()
           ^^^^^^^^^^^^^^
  File "/home/airflow/.local/lib/python3.12/site-packages/sqlalchemy/future/engine.py", line 412, in connect
    return super(Engine, self).connect()
           ^^^^^^^^^^^^^^^^^^^^^^^^^^^^^
  File "/home/airflow/.local/lib/python3.12/site-packages/sqlalchemy/engine/base.py", line 3325, in connect
    return self._connection_cls(self, close_with_result=close_with_result)
           ^^^^^^^^^^^^^^^^^^^^^^^^^^^^^^^^^^^^^^^^^^^^^^^^^^^^^^^^^^^^^^^
  File "/home/airflow/.local/lib/python3.12/site-packages/sqlalchemy/engine/base.py", line 96, in __init__
    else engine.raw_connection()
         ^^^^^^^^^^^^^^^^^^^^^^^
  File "/home/airflow/.local/lib/python3.12/site-packages/sqlalchemy/engine/base.py", line 3404, in raw_connection
    return self._wrap_pool_connect(self.pool.connect, _connection)
           ^^^^^^^^^^^^^^^^^^^^^^^^^^^^^^^^^^^^^^^^^^^^^^^^^^^^^^^
  File "/home/airflow/.local/lib/python3.12/site-packages/sqlalchemy/engine/base.py", line 3374, in _wrap_pool_connect
    Connection._handle_dbapi_exception_noconnection(
  File "/home/airflow/.local/lib/python3.12/site-packages/sqlalchemy/engine/base.py", line 2208, in _handle_dbapi_exception_noconnection
    util.raise_(
  File "/home/airflow/.local/lib/python3.12/site-packages/sqlalchemy/util/compat.py", line 211, in raise_
    raise exception
  File "/home/airflow/.local/lib/python3.12/site-packages/sqlalchemy/engine/base.py", line 3371, in _wrap_pool_connect
    return fn()
           ^^^^
  File "/home/airflow/.local/lib/python3.12/site-packages/sqlalchemy/pool/base.py", line 327, in connect
    return _ConnectionFairy._checkout(self)
           ^^^^^^^^^^^^^^^^^^^^^^^^^^^^^^^^
  File "/home/airflow/.local/lib/python3.12/site-packages/sqlalchemy/pool/base.py", line 894, in _checkout
    fairy = _ConnectionRecord.checkout(pool)
            ^^^^^^^^^^^^^^^^^^^^^^^^^^^^^^^^
  File "/home/airflow/.local/lib/python3.12/site-packages/sqlalchemy/pool/base.py", line 493, in checkout
    rec = pool._do_get()
          ^^^^^^^^^^^^^^
  File "/home/airflow/.local/lib/python3.12/site-packages/sqlalchemy/pool/impl.py", line 256, in _do_get
    return self._create_connection()
           ^^^^^^^^^^^^^^^^^^^^^^^^^
  File "/home/airflow/.local/lib/python3.12/site-packages/sqlalchemy/pool/base.py", line 273, in _create_connection
    return _ConnectionRecord(self)
           ^^^^^^^^^^^^^^^^^^^^^^^
  File "/home/airflow/.local/lib/python3.12/site-packages/sqlalchemy/pool/base.py", line 388, in __init__
    self.__connect()
  File "/home/airflow/.local/lib/python3.12/site-packages/sqlalchemy/pool/base.py", line 690, in __connect
    with util.safe_reraise():
         ^^^^^^^^^^^^^^^^^^^
  File "/home/airflow/.local/lib/python3.12/site-packages/sqlalchemy/util/langhelpers.py", line 70, in __exit__
    compat.raise_(
  File "/home/airflow/.local/lib/python3.12/site-packages/sqlalchemy/util/compat.py", line 211, in raise_
    raise exception
  File "/home/airflow/.local/lib/python3.12/site-packages/sqlalchemy/pool/base.py", line 686, in __connect
    self.dbapi_connection = connection = pool._invoke_creator(self)
                                         ^^^^^^^^^^^^^^^^^^^^^^^^^^
  File "/home/airflow/.local/lib/python3.12/site-packages/sqlalchemy/engine/create.py", line 574, in connect
    return dialect.connect(*cargs, **cparams)
           ^^^^^^^^^^^^^^^^^^^^^^^^^^^^^^^^^^
  File "/home/airflow/.local/lib/python3.12/site-packages/sqlalchemy/engine/default.py", line 598, in connect
    return self.dbapi.connect(*cargs, **cparams)
           ^^^^^^^^^^^^^^^^^^^^^^^^^^^^^^^^^^^^^
  File "/home/airflow/.local/lib/python3.12/site-packages/psycopg2/__init__.py", line 122, in connect
    conn = _connect(dsn, connection_factory=connection_factory, **kwasync)
           ^^^^^^^^^^^^^^^^^^^^^^^^^^^^^^^^^^^^^^^^^^^^^^^^^^^^^^^^^^^^^^^
sqlalchemy.exc.OperationalError: (psycopg2.OperationalError) could not translate host name "postgres" to address: Temporary failure in name resolution

(Background on this error at: https://sqlalche.me/e/14/e3q8)
[2025-01-27T06:15:09.904+0000] {local_task_job_runner.py:245} INFO - ::endgroup::
